<?xml version="1.0" ?>
<!-- =================================================================================== -->
<!-- |    This document was autogenerated by xacro from cobot.xacro                    | -->
<!-- |    EDITING THIS FILE BY HAND IS NOT RECOMMENDED                                 | -->
<!-- =================================================================================== -->
<robot name="cobot">
  <material name="silver">
    <color rgba="0.700 0.700 0.700 1.000"/>
  </material>
  <transmission name="Joint1_tran">
    <type>transmission_interface/SimpleTransmission</type>
    <joint name="Joint1">
      <hardwareInterface>hardware_interface/EffortJointInterface</hardwareInterface>
    </joint>
    <actuator name="Joint1_actr">
      <hardwareInterface>hardware_interface/EffortJointInterface</hardwareInterface>
      <mechanicalReduction>1</mechanicalReduction>
    </actuator>
  </transmission>
  <transmission name="Joint2_tran">
    <type>transmission_interface/SimpleTransmission</type>
    <joint name="Joint2">
      <hardwareInterface>hardware_interface/EffortJointInterface</hardwareInterface>
    </joint>
    <actuator name="Joint2_actr">
      <hardwareInterface>hardware_interface/EffortJointInterface</hardwareInterface>
      <mechanicalReduction>1</mechanicalReduction>
    </actuator>
  </transmission>
  <transmission name="Joint3_tran">
    <type>transmission_interface/SimpleTransmission</type>
    <joint name="Joint3">
      <hardwareInterface>hardware_interface/EffortJointInterface</hardwareInterface>
    </joint>
    <actuator name="Joint3_actr">
      <hardwareInterface>hardware_interface/EffortJointInterface</hardwareInterface>
      <mechanicalReduction>1</mechanicalReduction>
    </actuator>
  </transmission>
  <transmission name="Joint4_tran">
    <type>transmission_interface/SimpleTransmission</type>
    <joint name="Joint4">
      <hardwareInterface>hardware_interface/EffortJointInterface</hardwareInterface>
    </joint>
    <actuator name="Joint4_actr">
      <hardwareInterface>hardware_interface/EffortJointInterface</hardwareInterface>
      <mechanicalReduction>1</mechanicalReduction>
    </actuator>
  </transmission>
  <gazebo>
    <plugin filename="libgazebo_ros_control.so" name="control"/>
  </gazebo>
  <gazebo reference="base_link">
    <material>Gazebo/Silver</material>
    <mu1>0.2</mu1>
    <mu2>0.2</mu2>
    <self_collide>true</self_collide>
    <gravity>true</gravity>
  </gazebo>
  <gazebo reference="Link1_1">
    <material>Gazebo/Silver</material>
    <mu1>0.2</mu1>
    <mu2>0.2</mu2>
    <self_collide>true</self_collide>
  </gazebo>
  <gazebo reference="Link2_1">
    <material>Gazebo/Silver</material>
    <mu1>0.2</mu1>
    <mu2>0.2</mu2>
    <self_collide>true</self_collide>
  </gazebo>
  <gazebo reference="Link3_1">
    <material>Gazebo/Silver</material>
    <mu1>0.2</mu1>
    <mu2>0.2</mu2>
    <self_collide>true</self_collide>
  </gazebo>
  <gazebo reference="Link4_1">
    <material>Gazebo/Silver</material>
    <mu1>0.2</mu1>
    <mu2>0.2</mu2>
    <self_collide>true</self_collide>
  </gazebo>
  <link name="base_link">
    <inertial>
      <origin rpy="0 0 0" xyz="-1.1580046200244058e-17 5.790023100122029e-18 0.024999999999999994"/>
      <mass value="3.082687791334984"/>
      <inertia ixx="0.002569" ixy="-0.0" ixz="-0.0" iyy="0.002569" iyz="-0.0" izz="0.003853"/>
    </inertial>
    <visual>
      <origin rpy="0 0 0" xyz="0 0 0"/>
      <geometry>
        <mesh filename="meshes/base_link.stl" scale="0.001 0.001 0.001"/>
      </geometry>
      <material name="silver"/>
    </visual>
    <collision>
      <origin rpy="0 0 0" xyz="0 0 0"/>
      <geometry>
        <mesh filename="meshes/base_link.stl" scale="0.001 0.001 0.001"/>
      </geometry>
    </collision>
  </link>
  <link name="Link1_1">
    <inertial>
      <origin rpy="0 0 0" xyz="0.02283653671191256 0.0 0.042254276225913934"/>
      <mass value="6.383618554951958"/>
      <inertia ixx="0.008001" ixy="0.0" ixz="-0.001547" iyy="0.010215" iyz="-0.0" izz="0.010193"/>
    </inertial>
    <visual>
      <origin rpy="0 0 0" xyz="-0.0 -0.0 -0.05"/>
      <geometry>
        <mesh filename="meshes/Link1_1.stl" scale="0.001 0.001 0.001"/>
      </geometry>
      <material name="silver"/>
    </visual>
    <collision>
      <origin rpy="0 0 0" xyz="-0.0 -0.0 -0.05"/>
      <geometry>
        <mesh filename="meshes/Link1_1.stl" scale="0.001 0.001 0.001"/>
      </geometry>
    </collision>
  </link>
  <link name="Link2_1">
    <inertial>
      <origin rpy="0 0 0" xyz="0.05960014559509928 0.0 0.029646973179353442"/>
      <mass value="9.466306346286949"/>
      <inertia ixx="0.019973" ixy="-0.0" ixz="-0.00474" iyy="0.023271" iyz="0.0" izz="0.015131"/>
    </inertial>
    <visual>
      <origin rpy="0 0 0" xyz="-0.075 0.0 -0.1"/>
      <geometry>
        <mesh filename="meshes/Link2_1.stl" scale="0.001 0.001 0.001"/>
      </geometry>
      <material name="silver"/>
    </visual>
    <collision>
      <origin rpy="0 0 0" xyz="-0.075 0.0 -0.1"/>
      <geometry>
        <mesh filename="meshes/Link2_1.stl" scale="0.001 0.001 0.001"/>
      </geometry>
    </collision>
  </link>
  <link name="Link3_1">
    <inertial>
      <origin rpy="0 0 0" xyz="-0.018395006966072047 2.70267529470481e-17 0.0566049930339278"/>
      <mass value="7.924962450619444"/>
      <inertia ixx="0.012767" ixy="0.0" ixz="0.003099" iyy="0.015628" iyz="0.0" izz="0.012767"/>
    </inertial>
    <visual>
      <origin rpy="0 0 0" xyz="-0.15 -0.0 -0.2"/>
      <geometry>
        <mesh filename="meshes/Link3_1.stl" scale="0.001 0.001 0.001"/>
      </geometry>
      <material name="silver"/>
    </visual>
    <collision>
      <origin rpy="0 0 0" xyz="-0.15 -0.0 -0.2"/>
      <geometry>
        <mesh filename="meshes/Link3_1.stl" scale="0.001 0.001 0.001"/>
      </geometry>
    </collision>
  </link>
  <link name="Link4_1">
    <inertial>
      <origin rpy="0 0 0" xyz="-0.04225427622591337 -5.592073952616691e-18 0.022836536711913324"/>
      <mass value="6.383618554951956"/>
      <inertia ixx="0.010193" ixy="-0.0" ixz="0.001547" iyy="0.010215" iyz="0.0" izz="0.008001"/>
    </inertial>
    <visual>
      <origin rpy="0 0 0" xyz="-0.075 -0.0 -0.275"/>
      <geometry>
        <mesh filename="meshes/Link4_1.stl" scale="0.001 0.001 0.001"/>
      </geometry>
      <material name="silver"/>
    </visual>
    <collision>
      <origin rpy="0 0 0" xyz="-0.075 -0.0 -0.275"/>
      <geometry>
        <mesh filename="meshes/Link4_1.stl" scale="0.001 0.001 0.001"/>
      </geometry>
    </collision>
  </link>
  <joint name="Joint1" type="continuous">
    <origin rpy="0 0 0" xyz="0.0 0.0 0.05"/>
    <parent link="base_link"/>
    <child link="Link1_1"/>
    <axis xyz="0.0 0.0 1.0"/>
  </joint>
  <joint name="Joint2" type="continuous">
    <origin rpy="0 0 0" xyz="0.075 -0.0 0.05"/>
    <parent link="Link1_1"/>
    <child link="Link2_1"/>
    <axis xyz="1.0 0.0 0.0"/>
  </joint>
  <joint name="Joint3" type="continuous">
    <origin rpy="0 0 0" xyz="0.075 0.0 0.1"/>
    <parent link="Link2_1"/>
    <child link="Link3_1"/>
    <axis xyz="0.0 0.0 1.0"/>
  </joint>
  <joint name="Joint4" type="continuous">
    <origin rpy="0 0 0" xyz="-0.075 0.0 0.075"/>
    <parent link="Link3_1"/>
    <child link="Link4_1"/>
    <axis xyz="-1.0 0.0 0.0"/>
  </joint>
</robot>